Workbook

Sheet Start Here
A1: Preprocessing Pipeline – INT Incremental Update Tests (16 scenarios)
A3: How to use
A4: 1. Fill the YELLOW values in the table below once (bucket names, API URL, new page IDs). Every query in this workbook updates automatically.
A5: 2. Do the 'Setup' sheet once. Then do the scenario sheets in the RUN ORDER shown at the bottom (tabs are already in that order).
A6: 3. In each scenario sheet, follow the steps top to bottom. Column D is ready to copy: click the cell, Ctrl+C, paste into Spanner Studio / Bruno / GCS filter.
A7: 4. Step 1 of every sheet gives you a start time: paste it into the yellow 'Start time' cell at the top of that sheet – the queries below it use it.
A8: 5. Write what you see in 'Actual result', mark each step Pass/Fail, then set the sheet's 'Overall result'. Evidence: Spanner Studio → Results → Export → CSV (or screenshot).
A9: 6. If a Bruno call fails (API not available on INT), wait for the scheduled run (every 30 min) instead and continue from the 'Confirm the pipeline finished' step.
A10: 7. Only edit the QA test pages under Test Area. Never edit real content, and never touch 'QE' / 'Sanity Tests'.
A11: Tip: queries are on one line so they copy cleanly – press 'Format' in Spanner Studio to make them readable.
A13: Environment
B14: Athena (INT) | C14: https://lloyds-banking-test.eu1prod.expert.nicecxone.com → Customer Vulnerability Hub 2 › Vulnerabilities › Test Area
B15: Spanner Studio | C15: https://console.cloud.google.com/spanner/instances/ew2-int-wrk01-spi-ka-spanner/databases/hive-int-context-layer-db/details/query?project=wrk-int-wrk01-svp-dfadf4
B16: GCP project / instance / DB | C16: wrk-int-wrk01-svp-dfadf4 / ew2-int-wrk01-spi-ka-spanner / hive-int-context-layer-db
B17: GCS | C17: Console → Cloud Storage → Buckets
B18: Bruno | C18: Collection hive-knowledge-preprocessing → environment INT → requests: incremental-job, job-status
A20: Values used by the queries (yellow = fill in; grey = already known)
A21: # | B21: What | C21: Value | D21: Where to get it | E21: Name
A22: 1 | B22: Tracked root: Customer Vulnerability Hub 2 | C22: 39960 | D22: Known | E22: ID_ROOT
A23: 2 | B23: Test Area page | C23: 43599 | D23: Known | E23: ID_TA
A24: 3 | B24: Parent A page | C24: 43601 | D24: Known | E24: ID_PA
A25: 4 | B25: Parent B page | C25: 43603 | D25: Known | E25: ID_PB
A26: 5 | B26: Child AA page | C26: 43609 | D26: Known | E26: ID_AA
A27: 6 | B27: Child B page | C27: 43607 | D27: Known | E27: ID_B
A28: 7 | B28: Child C page | C28: <CHILD_C_ID> | D28: Setup sheet, step 9 | E28: ID_C
A29: 8 | B29: QA Delete Me S5 page | C29: <S5_ID> | D29: Setup sheet, step 9 | E29: ID_S5
A30: 9 | B30: QA Link Target S14 page | C30: <S14_ID> | D30: Setup sheet, step 9 | E30: ID_S14
A31: 10 | B31: QA Multi-Link S15 page | C31: <S15_ID> | D31: Setup sheet, step 9 | E31: ID_S15
A32: 11 | B32: External Support (real page, link target only) | C32: <REAL_ID> | D32: Setup sheet, step 10 | E32: ID_REAL
A33: 12 | B33: QA New Page S1 page | C33: <S1_ID> | D33: S01 step 5 | E33: ID_S1
... A38: 17 | B38: Pipeline API base URL (INT) | C38: <INT_BASE_URL> | D38: Setup sheet, step 1 (ask dev) | E38: API_URL
A40: Run order and results
A41: # | B41: Sheet | C41: Scenario | D41: Pages used | E41: Result
A42: 0 | B42: Setup | C42: do once before any scenario | D42: Test Area and all QA pages | E42: =Setup!C5 -> Not run
A43: 1 | B43: S01 | C43: New page created under a tracked root | D43: ="Parent A "&ID_PA&", Child B "&ID_B&", new page 'QA New Page S1'" -> Parent A 43601, Child B 43607, new page 'QA New Page S1' | E43: =S01!C5 -> Not run
A44: 2 | B44: S02 | C44: Existing page body text changed | D44: ="Child AA "&ID_AA -> Child AA 43609 | E44: =S02!C5 -> Not run
A45: 3 | B45: S03 | C45: Existing page updated: a link removed | D45: ="Child AA "&ID_AA&" (link to Child C "&ID_C&" is removed)" -> Child AA 43609 (link to Child C <CHILD_C_ID> is removed) | E45: =S03!C5 -> Not run
A46: 4 | B46: S04 | C46: Existing page updated: a new link added | D46: ="Child AA "&ID_AA&" (new link to Parent A "&ID_PA&")" -> Child AA 43609 (new link to Parent A 43601) | E46: =S04!C5 -> Not run
A47: 5 | B47: S05 | C47: Page hard-removed from Athena | D47: ="QA Delete Me S5 "&ID_S5&" (child of Parent A "&ID_PA&")" -> QA Delete Me S5 <S5_ID> (child of Parent A 43601) | E47: =S05!C5 -> Not run
A48: 6 | B48: S06 | C48: Metadata-only change (title only) | D48: ="Child B "&ID_B -> Child B 43607 | E48: =S06!C5 -> Not run
...

Sheet Setup
A1: SETUP – do once before any scenario
B2: Goal | C2: Check INT is ready, build the test content in Athena, run the pipeline once, and record page IDs.
B3: Pages used | C3: Test Area and all QA pages
B4: Start time (UTC) | C4: <paste start time from step 1>
B5: Overall result | C5: Not run
A7: Step | B7: Where | C7: What to do | D7: Copy this (query / path / URL) | E7: Expected result (fields & values) | F7: Actual result | G7: Pass / Fail
A8: 1 | B8: Dev / Teams | C8: Ask the dev team to confirm: (1) the new build is deployed to INT, (2) database migration applied, (3) the INT API base URL for Bruno, (4) who can create a controlled failure for S09. Put the URL on 'Start Here'. | D8: - | E8: All 4 confirmed.
A9: 2 | B9: Spanner Studio | C9: Check the tables exist. | D9: SELECT table_name FROM information_schema.tables WHERE table_schema = '' ORDER BY table_name | E9: List includes: job, page, page_audit, page_dependency, page_since. If 'job' is missing → STOP (INT not upgraded yet; it was missing on 29-Sep).
A10: 3 | B10: Spanner Studio | C10: Check the audit table has the new column. | D10: SELECT COUNT(*) AS n FROM information_schema.columns WHERE table_name = 'page_audit' AND column_name = 'job_type' | E10: n = 1. If 0 → STOP (old schema).
A11: 4 | B11: GCS (Console) | C11: Find the 3 buckets used by the pipeline (HTML, JSON, Markdown) and the top-level folder inside them. Open the JSON bucket and look for a folder containing 43609. Write the names on 'Start Here'. | D11: - | E11: Bucket names and folder recorded on 'Start Here'.
A12: 5 | B12: Athena | C12: Build the test content: edit / create every page in the table 'Test content' at the bottom of this sheet. Paste the body text exactly and add the links listed. Create the 3 new pages under Parent A. Do NOT create 'QA New Page S1' yet. | D12: - | E12: All pages exist in Athena with the given text and links.
A13: 6 | B13: Spanner Studio | C13: Record the start time. Run the query, copy the value and paste it into the yellow 'Start time' cell (C4) at the top of this sheet. | D13: SELECT CURRENT_TIMESTAMP() AS start_time | E13: One value like 2026-10-01T09:15:02.123456Z. After pasting it into C4, the queries below show it automatically.
A14: 7 | B14: Bruno | C14: Trigger the pipeline: open Bruno → collection hive-knowledge-preprocessing → environment INT → request 'incremental-job' → Send. Copy the job_id from the response. Open request 'job-status', put the job_id at the end of the URL, Send every ~1 minute until status is SUCCESS. | D14: ="POST "&API_URL&"/api/v1/jobs/incremental then GET "&API_URL&"/api/v1/jobs/<job_id>" -> POST <INT_BASE_URL>/api/v1/jobs/incremental then GET <INT_BASE_URL>/api/v1/jobs/<job_id> | E14: incremental-job returns a job_id. job-status ends with status = SUCCESS (not FAILED). If FAILED: screenshot the response, mark this sheet Fail, log a defect.
A15: 8 | B15: Spanner Studio | C15: Confirm the pipeline finished (a new run for root 39960 after your start time). | D15: ="SELECT page_id, job_run_id, status, since_time, watermark_time, ingested_at FROM page_since WHERE page_id = '"&ID_ROOT&"' AND ingested_at > TIMESTAMP('"&$C$4&"') ORDER BY ingested_at DESC" -> SELECT page_id, job_run_id, status, since_time, watermark_time, ingested_at FROM page_since WHERE page_id = '39960' AND ingested_at > TIMESTAMP('<paste start time from step 1>') ORDER BY ingested_at DESC | E15: At least 1 row: page_id = 39960, status = COMPLETED, ingested_at later than your start time. No row yet → wait a minute and re-run.
A16: 9 | B16: Spanner Studio | C16: Get the page IDs of the Test Area pages. Copy the IDs of Child C, QA Delete Me S5, QA Link Target S14, QA Multi-Link S15 into the yellow cells on 'Start Here'. | D16: SELECT page_id, title, page_type, revision, path, summary IS NOT NULL AS has_summary, ingested_at FROM page WHERE path LIKE 'Customer_Vulnerability_Hub_2/Vulnerabilities/Test_Area%' ORDER BY path | E16: Rows for: Test Area 43599, Parent A 43601, Parent B 43603, Child AA 43609 (path now ends /Parent_B/Child_AA), Child B 43607, Child C, QA Delete Me S5, QA Link Target S14, QA Multi-Link S15. has_summary = true for the content pages. Child A (43605) should NOT be listed if it no longer exists in Athena (if it is → log observation).
A17: 10 | B17: Spanner Studio | C17: Get the ID of the real page 'External Support' and put it on 'Start Here'. | D17: SELECT page_id, title, path FROM page WHERE title = 'External Support' AND path LIKE 'Customer_Vulnerability_Hub_2%' | E17: 1 row.
A18: 11 | B18: Spanner Studio | C18: Save the baseline of all Test Area links (Export → CSV, name it Setup_links_baseline). | D18: ="SELECT page_id, dependency_page_id, type, relationship_label, is_broken FROM page_dependency WHERE page_id IN ('"&ID_PA&"','"&ID_PB&"','"&ID_AA&"','"&ID_B&"','"&ID_C&"','"&ID_S5&"','"&ID_S14&"','"&ID_S15&"') ORDER BY page_id, dependency_page_id" -> SELECT page_id, dependency_page_id, type, relationship_label, is_broken FROM page_dependency WHERE page_id IN ('43601','43603','43609','43607','<CHILD_C_ID>','<S5_ID>','<S14_ID>','<S15_ID>') ORDER BY page_id, dependency_page_id | E18: Parent A → Child AA, QA Link Target S14 (internal) + subpage rows to its child pages. Parent B → Child B (internal) + subpage rows to Child AA, Child B, Child C. Child AA → Child B, Child C, External Support (internal) and '00000' (external). Child C → Child B. QA Multi-Link S15 → Child AA, Child B, Child C. is_broken = false everywhere.
A19: 12 | B19: GCS (Console) | C19: Cloud Storage → Buckets → open the bucket shown → in 'Filter by name prefix' paste the path → open metadata.json. | D19: ="Bucket: "&GCS_JSON&" Path: "&GCS_FOLDER&"/"&ID_AA&"/metadata.json" -> Bucket: <JSON_BUCKET> Path: <FOLDER>/43609/metadata.json | E19: File exists and its 'Updated' time is after your start time.
A22: Test content (used by Setup step 5) – build exactly this in Athena under Test Area
A23: # | B23: Page | C23: Where / action | D23: Body text to paste | E23: Links to add (text → internal page) | F23: Used in
A24: 1 | B24: Parent A | C24: Test Area → edit body | D24: QA-ZX91 Parent A. Test content for preprocessing pipeline testing only – not real guidance. Overview: This section groups QA test pages. See Child AA and the Link target page. | E24: 'Child AA' → Child AA 'Link target' → QA Link Target S14 (add after creating it) | F24: S04, S10, S14
A25: 2 | B25: Parent B | C25: Test Area → edit body | D25: QA-ZX91 Parent B. Test content for preprocessing pipeline testing only – not real guidance. Overview: This section holds the child pages used for update tests. See Child B. | E25: 'Child B' → Child B | F25: S08, S10
A26: 3 | B26: Child AA | C26: under Parent B → edit body | D26: QA-ZX91 Child AA procedure. Test content only – not real guidance. Step 1: The colleague opens the QA test record and checks the reference. Step 2: The colleague follows the next steps in Child B and Child C. See also External Support and the Example site. | E26: 'Child B' → Child B 'Child C' → Child C 'External Support' → External Support (real page) 'Example site' → https://example.com/qa-zx91 | F26: S02, S03, S04
A27: 4 | B27: Child B | C27: under Parent B → edit body | D27: QA-ZX91 Child B reference. Test content only – not real guidance. Details: Reference information for the QA test record. | E27: (none) | F27: S06, S09, S11, S16
A28: 5 | B28: Child C | C28: under Parent B → edit body | D28: QA-ZX91 Child C reference. Test content only – not real guidance. Details: Additional reference information. See Child B. | E28: 'Child B' → Child B | F28: S07, S10
A29: 6 | B29: QA Delete Me S5 | C29: under Parent A → CREATE | D29: QA-ZX91 page to be deleted in scenario S5. Test content only. | E29: (none) | F29: S05
A30: 7 | B30: QA Link Target S14 | C30: under Parent A → CREATE | D30: QA-ZX91 link target – will be deleted in scenario S14. Test content only. | E30: (none) | F30: S14
A31: 8 | B31: QA Multi-Link S15 | C31: under Parent A → CREATE | D31: QA-ZX91 multi-link test page. Test content only. Related: Child AA, Child B, Child C. | E31: 'Child AA' → Child AA 'Child B' → Child B 'Child C' → Child C | F31: S15
A32: 9 | B32: QE / Sanity Tests | C32: DO NOT TOUCH | D32: - | E32: - | F32: -

Sheet S01
A1: S01 – New page created under a tracked root
B2: Goal | C2: A new Athena page is picked up, tagged by the LLM and stored in Spanner + GCS with its links.
B3: Pages used | C3: ="Parent A "&ID_PA&", Child B "&ID_B&", new page 'QA New Page S1'" -> Parent A 43601, Child B 43607, new page 'QA New Page S1'
B4: Start time (UTC) | C4: <paste start time from step 1>
B5: Overall result | C5: Not run
A7: Step | B7: Where | C7: What to do | D7: Copy this (query / path / URL) | E7: Expected result (fields & values) | F7: Actual result | G7: Pass / Fail
A8: 1 | B8: Spanner Studio | C8: Record the start time. Run the query, copy the value and paste it into the yellow 'Start time' cell (C4) at the top of this sheet. | D8: SELECT CURRENT_TIMESTAMP() AS start_time | E8: One value like 2026-10-01T09:15:02.123456Z. After pasting it into C4, the queries below show it automatically.
A9: 2 | B9: Athena | C9: Go to Test Area → Parent A → New → New page. Title: QA New Page S1. Body (paste exactly): QA-ZX91 New Page S1. Test content only – not real guidance. Overview: This page was created to test new-page detection. See Child B. Select the words 'Child B' → Link → choose internal page Child B. Publish. | D9: - | E9: Page published under Parent A.
A10: 3 | B10: Bruno | C10: Trigger the pipeline: open Bruno → collection hive-knowledge-preprocessing → environment INT → request 'incremental-job' → Send. Copy the job_id from the response. Open request 'job-status', put the job_id at the end of the URL, Send every ~1 minute until status is SUCCESS. | D10: ="POST "&API_URL&"/api/v1/jobs/incremental then GET "&API_URL&"/api/v1/jobs/<job_id>" -> POST <INT_BASE_URL>/api/v1/jobs/incremental then GET <INT_BASE_URL>/api/v1/jobs/<job_id> | E10: incremental-job returns a job_id. job-status ends with status = SUCCESS (not FAILED). If FAILED: screenshot the response, mark this sheet Fail, log a defect.
A11: 4 | B11: Spanner Studio | C11: Confirm the pipeline finished (a new run for root 39960 after your start time). | D11: ="SELECT page_id, job_run_id, status, since_time, watermark_time, ingested_at FROM page_since WHERE page_id = '"&ID_ROOT&"' AND ingested_at > TIMESTAMP('"&$C$4&"') ORDER BY ingested_at DESC" -> SELECT page_id, job_run_id, status, since_time, watermark_time, ingested_at FROM page_since WHERE page_id = '39960' AND ingested_at > TIMESTAMP('<paste start time from step 1>') ORDER BY ingested_at DESC | E11: At least 1 row: page_id = 39960, status = COMPLETED, ingested_at later than your start time. No row yet → wait a minute and re-run.
A12: 5 | B12: Spanner Studio | C12: Find the new page and copy its page_id into 'Start Here' (QA New Page S1). | D12: SELECT page_id, title, path, revision FROM page WHERE title = 'QA New Page S1' | E12: Exactly 1 row. path = Customer_Vulnerability_Hub_2/Vulnerabilities/Test_Area/Parent_A/QA_New_Page_S1 (or Athena's URL for it). revision = the revision shown in Athena page history.
A13: 6 | B13: Spanner Studio | C13: Check the page row and its LLM metadata. | D13: ="SELECT page_id, title, page_type, revision, deleted, unpublished, content_size, summary, systems, channels, primary_intents, confidence_score, source_object_name, ingested_at FROM page WHERE page_id ="&" '"&ID_S1&"'" -> SELECT page_id, title, page_type, revision, deleted, unpublished, content_size, summary, systems, channels, primary_intents, confidence_score, source_object_name, ingested_at FROM page WHERE page_id = '<S1_ID>' | E13: title = QA New Page S1 · deleted = false · unpublished = false · content_size > 0 · summary not empty · primary_intents has at least 1 value · confidence_score between 0 and 1 · source_object_name not empty · ingested_at after start time.
A14: 7 | B14: Spanner Studio | C14: Check the link from the new page to Child B. | D14: ="SELECT page_id, dependency_page_id, type, relationship_label, relationship_confidence, relationship_reasoning, is_broken FROM page_dependency WHERE page_id = '"&ID_S1&"'" -> SELECT page_id, dependency_page_id, type, relationship_label, relationship_confidence, relationship_reasoning, is_broken FROM page_dependency WHERE page_id = '<S1_ID>' | E14: ="1 row: dependency_page_id = "&ID_B&" · type = internal · relationship_label = one of escalation / next_step / prerequisite / conditional_guidance / procedural_guidance · relationship_confidence between 0 and 1 · relationship_reasoning n"&"ot empty · is_broken = false." -> 1 row: dependency_page_id = 43607 · type = internal · relationship_label = one of escalation / next_step / prerequisite / conditional_guidance / procedural_guidance · relationship_confidence between 0 and 1 · relationship_reasoning not empty · is_broken = false.
A15: 8 | B15: Spanner Studio | C15: Check the parent (Parent A) now links to the new page. | D15: ="SELECT page_id, dependency_page_id, type FROM page_dependency WHERE dependency_page_id = '"&ID_S1&"'" -> SELECT page_id, dependency_page_id, type FROM page_dependency WHERE dependency_page_id = '<S1_ID>' | E15: ="1 row: page_id = "&ID_PA&" (Parent A) · type = subpage." -> 1 row: page_id = 43601 (Parent A) · type = subpage.
A16: 9 | B16: Spanner Studio | C16: Check the audit trail. | D16: ="SELECT page_id, job_type, load_type, status, has_errors, error_details, revision, ingested_at FROM page_audit WHERE page_id IN ('"&ID_S1&"') AND ingested_at > TIMESTAMP('"&$C$4&"') ORDER BY ingested_at" -> SELECT page_id, job_type, load_type, status, has_errors, error_details, revision, ingested_at FROM page_audit WHERE page_id IN ('<S1_ID>') AND ingested_at > TIMESTAMP('<paste start time from step 1>') ORDER BY ingested_at | E16: At least 1 row · job_type = incremental · last row status = completed · has_errors = false · no row with status = failed.
A17: 10 | B17: GCS (Console) | C17: Cloud Storage → Buckets → open the bucket shown → in 'Filter by name prefix' paste the path → open metadata.json. | D17: ="Bucket: "&GCS_JSON&" Path: "&GCS_FOLDER&"/"&ID_S1&"/metadata.json" -> Bucket: <JSON_BUCKET> Path: <FOLDER>/<S1_ID>/metadata.json | E17: Exists, Updated after start time. Download it: contains "QA New Page S1" and the Child B link.
A18: 11 | B18: GCS (Console) | C18: Cloud Storage → Buckets → open the bucket shown → in 'Filter by name prefix' paste the path → open page.md. | D18: ="Bucket: "&GCS_MD&" Path: "&GCS_FOLDER&"/"&ID_S1&"/page.md" -> Bucket: <MD_BUCKET> Path: <FOLDER>/<S1_ID>/page.md | E18: Exists, Updated after start time; text contains 'QA-ZX91 New Page S1'.
A19: 12 | B19: GCS (Console) | C19: Cloud Storage → Buckets → open the bucket shown → in 'Filter by name prefix' paste the path → open page.html. | D19: ="Bucket: "&GCS_HTML&" Path: "&GCS_FOLDER&"/"&ID_S1&"/page.html" -> Bucket: <HTML_BUCKET> Path: <FOLDER>/<S1_ID>/page.html | E19: Exists, Updated after start time.

Sheet S02
A1: S02 – Existing page body text changed
B2: Goal | C2: Editing the body of an existing page updates the SAME Spanner row (no duplicate) and refreshes the summary and GCS files.
B3: Pages used | C3: ="Child AA "&ID_AA -> Child AA 43609
B4: Start time (UTC) | C4: <paste start time from step 1>
B5: Overall result | C5: Not run
A7: Step | B7: Where | C7: What to do | D7: Copy this (query / path / URL) | E7: Expected result (fields & values) | F7: Actual result | G7: Pass / Fail
A8: 1 | B8: Spanner Studio | C8: Record the start time. Run the query, copy the value and paste it into the yellow 'Start time' cell (C4) at the top of this sheet. | D8: SELECT CURRENT_TIMESTAMP() AS start_time | E8: One value like 2026-10-01T09:15:02.123456Z. After pasting it into C4, the queries below show it automatically.
A9: 2 | B9: Spanner Studio | C9: BEFORE: save the current state (Export → CSV, name S02_before). | D9: ="SELECT page_id, title, revision, content_size, date_modified, summary, ingested_at FROM page WHERE page_id = '"&ID_AA&"'" -> SELECT page_id, title, revision, content_size, date_modified, summary, ingested_at FROM page WHERE page_id = '43609' | E9: 1 row. Note revision and content_size in 'Actual result'.
A10: 3 | B10: Athena | C10: Open Child AA → Edit. Replace the Step 1 sentence with: QA-ZX91 Step 1 UPDATED for S2: the colleague must record the test reference number. Do not change links. Publish. | D10: - | E10: Athena shows a new revision.
A11: 4 | B11: Bruno | C11: Trigger the pipeline: open Bruno → collection hive-knowledge-preprocessing → environment INT → request 'incremental-job' → Send. Copy the job_id from the response. Open request 'job-status', put the job_id at the end of the URL, Send every ~1 minute until status is SUCCESS. | D11: ="POST "&API_URL&"/api/v1/jobs/incremental then GET "&API_URL&"/api/v1/jobs/<job_id>" -> POST <INT_BASE_URL>/api/v1/jobs/incremental then GET <INT_BASE_URL>/api/v1/jobs/<job_id> | E11: incremental-job returns a job_id. job-status ends with status = SUCCESS (not FAILED). If FAILED: screenshot the response, mark this sheet Fail, log a defect.
A12: 5 | B12: Spanner Studio | C12: Confirm the pipeline finished (a new run for root 39960 after your start time). | D12: ="SELECT page_id, job_run_id, status, since_time, watermark_time, ingested_at FROM page_since WHERE page_id = '"&ID_ROOT&"' AND ingested_at > TIMESTAMP('"&$C$4&"') ORDER BY ingested_at DESC" -> SELECT page_id, job_run_id, status, since_time, watermark_time, ingested_at FROM page_since WHERE page_id = '39960' AND ingested_at > TIMESTAMP('<paste start time from step 1>') ORDER BY ingested_at DESC | E12: At least 1 row: page_id = 39960, status = COMPLETED, ingested_at later than your start time. No row yet → wait a minute and re-run.
A13: 6 | B13: Spanner Studio | C13: AFTER: check the page row changed. | D13: ="SELECT page_id, title, revision, content_size, date_modified, summary, ingested_at FROM page WHERE page_id = '"&ID_AA&"'" -> SELECT page_id, title, revision, content_size, date_modified, summary, ingested_at FROM page WHERE page_id = '43609' | E13: revision higher than BEFORE (= Athena) · content_size different from BEFORE · date_modified newer · summary not empty (refreshed) · ingested_at after start time.
A14: 7 | B14: Spanner Studio | C14: Check there is still only one row for the page. | D14: ="SELECT COUNT(*) AS n FROM page WHERE page_id = '"&ID_AA&"'" -> SELECT COUNT(*) AS n FROM page WHERE page_id = '43609' | E14: n = 1.
A15: 8 | B15: Spanner Studio | C15: Check links did not change. | D15: ="SELECT dependency_page_id, type, relationship_label, is_broken FROM page_dependency WHERE page_id = '"&ID_AA&"' ORDER BY dependency_page_id" -> SELECT dependency_page_id, type, relationship_label, is_broken FROM page_dependency WHERE page_id = '43609' ORDER BY dependency_page_id | E15: ="Same targets as in Setup_links_baseline for Child AA: "&ID_B&", "&ID_C&", "&ID_REAL&" (internal) and 00000 (external)." -> Same targets as in Setup_links_baseline for Child AA: 43607, <CHILD_C_ID>, <REAL_ID> (internal) and 00000 (external).
A16: 9 | B16: Spanner Studio | C16: Check the audit trail. | D16: ="SELECT page_id, job_type, load_type, status, has_errors, error_details, revision, ingested_at FROM page_audit WHERE page_id IN ('"&ID_AA&"') AND ingested_at > TIMESTAMP('"&$C$4&"') ORDER BY ingested_at" -> SELECT page_id, job_type, load_type, status, has_errors, error_details, revision, ingested_at FROM page_audit WHERE page_id IN ('43609') AND ingested_at > TIMESTAMP('<paste start time from step 1>') ORDER BY ingested_at | E16: job_type = incremental · last status = completed · has_errors = false · no failed rows.
A17: 10 | B17: GCS (Console) | C17: Cloud Storage → Buckets → open the bucket shown → in 'Filter by name prefix' paste the path → open page.md. | D17: ="Bucket: "&GCS_MD&" Path: "&GCS_FOLDER&"/"&ID_AA&"/page.md" -> Bucket: <MD_BUCKET> Path: <FOLDER>/43609/page.md | E17: Updated after start time. Text contains 'UPDATED for S2'.
A18: 11 | B18: GCS (Console) | C18: Cloud Storage → Buckets → open the bucket shown → in 'Filter by name prefix' paste the path → open metadata.json. | D18: ="Bucket: "&GCS_JSON&" Path: "&GCS_FOLDER&"/"&ID_AA&"/metadata.json" -> Bucket: <JSON_BUCKET> Path: <FOLDER>/43609/metadata.json | E18: Updated after start time.

Sheet S03
A1: S03 – Existing page updated: a link removed
B2: Goal | C2: When a hyperlink is removed from a page, its row in page_dependency is removed too (no stale link).
B3: Pages used | C3: ="Child AA "&ID_AA&" (link to Child C "&ID_C&" is removed)" -> Child AA 43609 (link to Child C <CHILD_C_ID> is removed)
B4: Start time (UTC) | C4: <paste start time from step 1>
B5: Overall result | C5: Not run
A7: Step | B7: Where | C7: What to do | D7: Copy this (query / path / URL) | E7: Expected result (fields & values) | F7: Actual result | G7: Pass / Fail
A8: 1 | B8: Spanner Studio | C8: Record the start time. Run the query, copy the value and paste it into the yellow 'Start time' cell (C4) at the top of this sheet. | D8: SELECT CURRENT_TIMESTAMP() AS start_time | E8: One value like 2026-10-01T09:15:02.123456Z. After pasting it into C4, the queries below show it automatically.
A9: 2 | B9: Spanner Studio | C9: BEFORE: save the current links (Export → CSV, name S03_before). | D9: ="SELECT dependency_page_id, type, href, is_broken FROM page_dependency WHERE page_id = '"&ID_AA&"' ORDER BY dependency_page_id" -> SELECT dependency_page_id, type, href, is_broken FROM page_dependency WHERE page_id = '43609' ORDER BY dependency_page_id | E9: ="Contains "&ID_C&" (Child C)." -> Contains <CHILD_C_ID> (Child C).
A10: 3 | B10: Athena | C10: Open Child AA → Edit. Delete the words 'Child C' together with their link. Publish. | D10: - | E10: New revision in Athena.
A11: 4 | B11: Bruno | C11: Trigger the pipeline: open Bruno → collection hive-knowledge-preprocessing → environment INT → request 'incremental-job' → Send. Copy the job_id from the response. Open request 'job-status', put the job_id at the end of the URL, Send every ~1 minute until status is SUCCESS. | D11: ="POST "&API_URL&"/api/v1/jobs/incremental then GET "&API_URL&"/api/v1/jobs/<job_id>" -> POST <INT_BASE_URL>/api/v1/jobs/incremental then GET <INT_BASE_URL>/api/v1/jobs/<job_id> | E11: incremental-job returns a job_id. job-status ends with status = SUCCESS (not FAILED). If FAILED: screenshot the response, mark this sheet Fail, log a defect.
A12: 5 | B12: Spanner Studio | C12: Confirm the pipeline finished (a new run for root 39960 after your start time). | D12: ="SELECT page_id, job_run_id, status, since_time, watermark_time, ingested_at FROM page_since WHERE page_id = '"&ID_ROOT&"' AND ingested_at > TIMESTAMP('"&$C$4&"') ORDER BY ingested_at DESC" -> SELECT page_id, job_run_id, status, since_time, watermark_time, ingested_at FROM page_since WHERE page_id = '39960' AND ingested_at > TIMESTAMP('<paste start time from step 1>') ORDER BY ingested_at DESC | E12: At least 1 row: page_id = 39960, status = COMPLETED, ingested_at later than your start time. No row yet → wait a minute and re-run.
A13: 6 | B13: Spanner Studio | C13: Check the Child C link is gone. | D13: ="SELECT COUNT(*) AS stale_rows FROM page_dependency WHERE page_id = '"&ID_AA&"' AND dependency_page_id = '"&ID_C&"'" -> SELECT COUNT(*) AS stale_rows FROM page_dependency WHERE page_id = '43609' AND dependency_page_id = '<CHILD_C_ID>' | E13: stale_rows = 0. If 1 → FAIL: stale dependency row (known risk – log a defect).
A14: 7 | B14: Spanner Studio | C14: Check the other links are still there. | D14: ="SELECT dependency_page_id, type, is_broken FROM page_dependency WHERE page_id = '"&ID_AA&"' ORDER BY dependency_page_id" -> SELECT dependency_page_id, type, is_broken FROM page_dependency WHERE page_id = '43609' ORDER BY dependency_page_id | E14: ="Contains "&ID_B&", "&ID_REAL&", 00000. Does NOT contain "&ID_C&". is_broken = false." -> Contains 43607, <REAL_ID>, 00000. Does NOT contain <CHILD_C_ID>. is_broken = false.
A15: 8 | B15: Spanner Studio | C15: Check the page was updated. | D15: ="SELECT revision, ingested_at FROM page WHERE page_id = '"&ID_AA&"'" -> SELECT revision, ingested_at FROM page WHERE page_id = '43609' | E15: revision higher than before · ingested_at after start time.
A16: 9 | B16: Spanner Studio | C16: Check the audit trail. | D16: ="SELECT page_id, job_type, load_type, status, has_errors, error_details, revision, ingested_at FROM page_audit WHERE page_id IN ('"&ID_AA&"') AND ingested_at > TIMESTAMP('"&$C$4&"') ORDER BY ingested_at" -> SELECT page_id, job_type, load_type, status, has_errors, error_details, revision, ingested_at FROM page_audit WHERE page_id IN ('43609') AND ingested_at > TIMESTAMP('<paste start time from step 1>') ORDER BY ingested_at | E16: last status = completed · no failed rows.
A17: 10 | B17: GCS (Console) | C17: Cloud Storage → Buckets → open the bucket shown → in 'Filter by name prefix' paste the path → open metadata.json. | D17: ="Bucket: "&GCS_JSON&" Path: "&GCS_FOLDER&"/"&ID_AA&"/metadata.json" -> Bucket: <JSON_BUCKET> Path: <FOLDER>/43609/metadata.json | E17: ="Updated after start time. Search the file for "&ID_C&": it must NOT appear in the relationship list." -> Updated after start time. Search the file for <CHILD_C_ID>: it must NOT appear in the relationship list.

Sheet S04
A1: S04 – Existing page updated: a new link added
B2: Goal | C2: When a hyperlink is added, a new page_dependency row is created with an LLM relationship label.
B3: Pages used | C3: ="Child AA "&ID_AA&" (new link to Parent A "&ID_PA&")" -> Child AA 43609 (new link to Parent A 43601)
B4: Start time (UTC) | C4: <paste start time from step 1>
B5: Overall result | C5: Not run
A7: Step | B7: Where | C7: What to do | D7: Copy this (query / path / URL) | E7: Expected result (fields & values) | F7: Actual result | G7: Pass / Fail
A8: 1 | B8: Spanner Studio | C8: Record the start time. Run the query, copy the value and paste it into the yellow 'Start time' cell (C4) at the top of this sheet. | D8: SELECT CURRENT_TIMESTAMP() AS start_time | E8: One value like 2026-10-01T09:15:02.123456Z. After pasting it into C4, the queries below show it automatically.
A9: 2 | B9: Spanner Studio | C9: BEFORE: count the current links. | D9: ="SELECT COUNT(*) AS links FROM page_dependency WHERE page_id = '"&ID_AA&"'" -> SELECT COUNT(*) AS links FROM page_dependency WHERE page_id = '43609' | E9: Note the number in 'Actual result'.
A10: 3 | B10: Athena | C10: Open Child AA → Edit. Add a new sentence at the end: 'Go to Parent A' and link the words 'Parent A' to the internal page Parent A. Publish. | D10: - | E10: New revision in Athena.
A11: 4 | B11: Bruno | C11: Trigger the pipeline: open Bruno → collection hive-knowledge-preprocessing → environment INT → request 'incremental-job' → Send. Copy the job_id from the response. Open request 'job-status', put the job_id at the end of the URL, Send every ~1 minute until status is SUCCESS. | D11: ="POST "&API_URL&"/api/v1/jobs/incremental then GET "&API_URL&"/api/v1/jobs/<job_id>" -> POST <INT_BASE_URL>/api/v1/jobs/incremental then GET <INT_BASE_URL>/api/v1/jobs/<job_id> | E11: incremental-job returns a job_id. job-status ends with status = SUCCESS (not FAILED). If FAILED: screenshot the response, mark this sheet Fail, log a defect.
A12: 5 | B12: Spanner Studio | C12: Confirm the pipeline finished (a new run for root 39960 after your start time). | D12: ="SELECT page_id, job_run_id, status, since_time, watermark_time, ingested_at FROM page_since WHERE page_id = '"&ID_ROOT&"' AND ingested_at > TIMESTAMP('"&$C$4&"') ORDER BY ingested_at DESC" -> SELECT page_id, job_run_id, status, since_time, watermark_time, ingested_at FROM page_since WHERE page_id = '39960' AND ingested_at > TIMESTAMP('<paste start time from step 1>') ORDER BY ingested_at DESC | E12: At least 1 row: page_id = 39960, status = COMPLETED, ingested_at later than your start time. No row yet → wait a minute and re-run.
A13: 6 | B13: Spanner Studio | C13: Check the new link row. | D13: ="SELECT dependency_page_id, type, relationship_label, relationship_confidence, relationship_reasoning, text, href, is_broken FROM page_dependency WHERE page_id = '"&ID_AA&"' AND dependency_page_id = '"&ID_PA&"'" -> SELECT dependency_page_id, type, relationship_label, relationship_confidence, relationship_reasoning, text, href, is_broken FROM page_dependency WHERE page_id = '43609' AND dependency_page_id = '43601' | E13: Exactly 1 row · type = internal · relationship_label = one of escalation / next_step / prerequisite / conditional_guidance / procedural_guidance · relationship_confidence between 0 and 1 · relationship_reasoning not empty · text contains 'Parent A' · is_broken = false.
A14: 7 | B14: Spanner Studio | C14: Check the link count went up by one. | D14: ="SELECT COUNT(*) AS links FROM page_dependency WHERE page_id = '"&ID_AA&"'" -> SELECT COUNT(*) AS links FROM page_dependency WHERE page_id = '43609' | E14: links = BEFORE + 1.
A15: 8 | B15: Spanner Studio | C15: Check the audit trail. | D15: ="SELECT page_id, job_type, load_type, status, has_errors, error_details, revision, ingested_at FROM page_audit WHERE page_id IN ('"&ID_AA&"') AND ingested_at > TIMESTAMP('"&$C$4&"') ORDER BY ingested_at" -> SELECT page_id, job_type, load_type, status, has_errors, error_details, revision, ingested_at FROM page_audit WHERE page_id IN ('43609') AND ingested_at > TIMESTAMP('<paste start time from step 1>') ORDER BY ingested_at | E15: last status = completed · no failed rows.
A16: 9 | B16: GCS (Console) | C16: Cloud Storage → Buckets → open the bucket shown → in 'Filter by name prefix' paste the path → open metadata.json. | D16: ="Bucket: "&GCS_JSON&" Path: "&GCS_FOLDER&"/"&ID_AA&"/metadata.json" -> Bucket: <JSON_BUCKET> Path: <FOLDER>/43609/metadata.json | E16: ="Updated after start time and contains "&ID_PA&"." -> Updated after start time and contains 43601.

Sheet S05
A1: S05 – Page hard-removed from Athena
B2: Goal | C2: A deleted Athena page is removed from Spanner (page + all its links) and from all 3 GCS buckets.
B3: Pages used | C3: ="QA Delete Me S5 "&ID_S5&" (child of Parent A "&ID_PA&")" -> QA Delete Me S5 <S5_ID> (child of Parent A 43601)
B4: Start time (UTC) | C4: <paste start time from step 1>
B5: Overall result | C5: Not run
A7: Step | B7: Where | C7: What to do | D7: Copy this (query / path / URL) | E7: Expected result (fields & values) | F7: Actual result | G7: Pass / Fail
A8: 1 | B8: Spanner Studio | C8: Record the start time. Run the query, copy the value and paste it into the yellow 'Start time' cell (C4) at the top of this sheet. | D8: SELECT CURRENT_TIMESTAMP() AS start_time | E8: One value like 2026-10-01T09:15:02.123456Z. After pasting it into C4, the queries below show it automatically.
A9: 2 | B9: Spanner Studio | C9: BEFORE: confirm the page and its links exist (Export → CSV, name S05_before). | D9: ="SELECT page_id, dependency_page_id, type FROM page_dependency WHERE page_id = '"&ID_S5&"' OR dependency_page_id = '"&ID_S5&"'" -> SELECT page_id, dependency_page_id, type FROM page_dependency WHERE page_id = '<S5_ID>' OR dependency_page_id = '<S5_ID>' | E9: ="At least the row page_id = "&ID_PA&" → "&ID_S5&", type = subpage." -> At least the row page_id = 43601 → <S5_ID>, type = subpage.
A10: 3 | B10: Athena | C10: Open QA Delete Me S5 → Options → Delete page → confirm. | D10: - | E10: Page no longer visible under Parent A.
A11: 4 | B11: Bruno | C11: Trigger the pipeline: open Bruno → collection hive-knowledge-preprocessing → environment INT → request 'incremental-job' → Send. Copy the job_id from the response. Open request 'job-status', put the job_id at the end of the URL, Send every ~1 minute until status is SUCCESS. | D11: ="POST "&API_URL&"/api/v1/jobs/incremental then GET "&API_URL&"/api/v1/jobs/<job_id>" -> POST <INT_BASE_URL>/api/v1/jobs/incremental then GET <INT_BASE_URL>/api/v1/jobs/<job_id> | E11: incremental-job returns a job_id. job-status ends with status = SUCCESS (not FAILED). If FAILED: screenshot the response, mark this sheet Fail, log a defect.
A12: 5 | B12: Spanner Studio | C12: Confirm the pipeline finished (a new run for root 39960 after your start time). | D12: ="SELECT page_id, job_run_id, status, since_time, watermark_time, ingested_at FROM page_since WHERE page_id = '"&ID_ROOT&"' AND ingested_at > TIMESTAMP('"&$C$4&"') ORDER BY ingested_at DESC" -> SELECT page_id, job_run_id, status, since_time, watermark_time, ingested_at FROM page_since WHERE page_id = '39960' AND ingested_at > TIMESTAMP('<paste start time from step 1>') ORDER BY ingested_at DESC | E12: At least 1 row: page_id = 39960, status = COMPLETED, ingested_at later than your start time. No row yet → wait a minute and re-run.
A13: 6 | B13: Spanner Studio | C13: Check the page row is gone. | D13: ="SELECT COUNT(*) AS n FROM page WHERE page_id = '"&ID_S5&"'" -> SELECT COUNT(*) AS n FROM page WHERE page_id = '<S5_ID>' | E13: n = 0.
A14: 7 | B14: Spanner Studio | C14: Check all links to/from it are gone. | D14: ="SELECT page_id, dependency_page_id, type FROM page_dependency WHERE page_id = '"&ID_S5&"' OR dependency_page_id = '"&ID_S5&"'" -> SELECT page_id, dependency_page_id, type FROM page_dependency WHERE page_id = '<S5_ID>' OR dependency_page_id = '<S5_ID>' | E14: 0 rows.
A15: 8 | B15: Spanner Studio | C15: Check the audit trail. | D15: ="SELECT page_id, job_type, load_type, status, has_errors, error_details, revision, ingested_at FROM page_audit WHERE page_id IN ('"&ID_S5&"', '"&ID_PA&"') AND ingested_at > TIMESTAMP('"&$C$4&"') ORDER BY ingested_at" -> SELECT page_id, job_type, load_type, status, has_errors, error_details, revision, ingested_at FROM page_audit WHERE page_id IN ('<S5_ID>', '43601') AND ingested_at > TIMESTAMP('<paste start time from step 1>') ORDER BY ingested_at | E15: ="Rows for "&ID_S5&" with load_type delete_page and/or purge_content, status = completed. No failed rows." -> Rows for <S5_ID> with load_type delete_page and/or purge_content, status = completed. No failed rows.
A16: 9 | B16: GCS (Console) | C16: Check the page's files are removed from ALL 3 buckets (repeat the filter in each bucket). | D16: ="Path: "&GCS_FOLDER&"/"&ID_S5&"/ in buckets "&GCS_JSON&", "&GCS_MD&", "&GCS_HTML -> Path: <FOLDER>/<S5_ID>/ in buckets <JSON_BUCKET>, <MD_BUCKET>, <HTML_BUCKET> | E16: No objects found in any of the 3 buckets.

Sheet S06
A1: S06 – Metadata-only change (title only)
B2: Goal | C2: Changing only the title updates the title/metadata, but content_size, links and page.md/page.html stay the same.
B3: Pages used | C3: ="Child B "&ID_B -> Child B 43607
B4: Start time (UTC) | C4: <paste start time from step 1>
B5: Overall result | C5: Not run
A7: Step | B7: Where | C7: What to do | D7: Copy this (query / path / URL) | E7: Expected result (fields & values) | F7: Actual result | G7: Pass / Fail
A8: 1 | B8: Spanner Studio | C8: Record the start time. Run the query, copy the value and paste it into the yellow 'Start time' cell (C4) at the top of this sheet. | D8: SELECT CURRENT_TIMESTAMP() AS start_time | E8: One value like 2026-10-01T09:15:02.123456Z. After pasting it into C4, the queries below show it automatically.
A9: 2 | B9: Spanner Studio | C9: BEFORE: save the page row (Export → CSV, name S06_before). | D9: ="SELECT page_id, title, path, revision, content_size, summary FROM page WHERE page_id = '"&ID_B&"'" -> SELECT page_id, title, path, revision, content_size, summary FROM page WHERE page_id = '43607' | E9: Note content_size and path.
A10: 3 | B10: GCS (Console) | C10: Cloud Storage → Buckets → open the bucket shown → in 'Filter by name prefix' paste the path → open page.md. | D10: ="Bucket: "&GCS_MD&" Path: "&GCS_FOLDER&"/"&ID_B&"/page.md" -> Bucket: <MD_BUCKET> Path: <FOLDER>/43607/page.md | E10: ="BEFORE: click the object → note its crc32c hash in 'Actual result'. Do the same for page.html in "&GCS_HTML&"." -> BEFORE: click the object → note its crc32c hash in 'Actual result'. Do the same for page.html in <HTML_BUCKET>.
A11: 4 | B11: Athena | C11: Open Child B → rename the title to: Child B Renamed QA-ZX91. Do NOT change the body. Save/Publish. | D11: - | E11: New title visible.
A12: 5 | B12: Bruno | C12: Trigger the pipeline: open Bruno → collection hive-knowledge-preprocessing → environment INT → request 'incremental-job' → Send. Copy the job_id from the response. Open request 'job-status', put the job_id at the end of the URL, Send every ~1 minute until status is SUCCESS. | D12: ="POST "&API_URL&"/api/v1/jobs/incremental then GET "&API_URL&"/api/v1/jobs/<job_id>" -> POST <INT_BASE_URL>/api/v1/jobs/incremental then GET <INT_BASE_URL>/api/v1/jobs/<job_id> | E12: incremental-job returns a job_id. job-status ends with status = SUCCESS (not FAILED). If FAILED: screenshot the response, mark this sheet Fail, log a defect.
A13: 6 | B13: Spanner Studio | C13: Confirm the pipeline finished (a new run for root 39960 after your start time). | D13: ="SELECT page_id, job_run_id, status, since_time, watermark_time, ingested_at FROM page_since WHERE page_id = '"&ID_ROOT&"' AND ingested_at > TIMESTAMP('"&$C$4&"') ORDER BY ingested_at DESC" -> SELECT page_id, job_run_id, status, since_time, watermark_time, ingested_at FROM page_since WHERE page_id = '39960' AND ingested_at > TIMESTAMP('<paste start time from step 1>') ORDER BY ingested_at DESC | E13: At least 1 row: page_id = 39960, status = COMPLETED, ingested_at later than your start time. No row yet → wait a minute and re-run.
A14: 7 | B14: Spanner Studio | C14: AFTER: check the page row. | D14: ="SELECT page_id, title, path, revision, content_size, summary, ingested_at FROM page WHERE page_id = '"&ID_B&"'" -> SELECT page_id, title, path, revision, content_size, summary, ingested_at FROM page WHERE page_id = '43607' | E14: title = Child B Renamed QA-ZX91 · revision higher · content_size = BEFORE (if different, record it – the title may be part of the content) · write down whether path and summary changed.
A15: 8 | B15: Spanner Studio | C15: Check links FROM Child B are unchanged. | D15: ="SELECT dependency_page_id, type FROM page_dependency WHERE page_id = '"&ID_B&"'" -> SELECT dependency_page_id, type FROM page_dependency WHERE page_id = '43607' | E15: Same as Setup_links_baseline (Child B has no content links).
A16: 9 | B16: Spanner Studio | C16: Check links TO Child B still work. | D16: ="SELECT page_id, dependency_page_id, type, is_broken, is_redirect FROM page_dependency WHERE dependency_page_id = '"&ID_B&"'" -> SELECT page_id, dependency_page_id, type, is_broken, is_redirect FROM page_dependency WHERE dependency_page_id = '43607' | E16: ="Rows from Child AA, Child C, Parent B (and QA pages) still point to "&ID_B&" · is_broken = false. Write down is_redirect." -> Rows from Child AA, Child C, Parent B (and QA pages) still point to 43607 · is_broken = false. Write down is_redirect.
A17: 10 | B17: Spanner Studio | C17: Check the audit trail. | D17: ="SELECT page_id, job_type, load_type, status, has_errors, error_details, revision, ingested_at FROM page_audit WHERE page_id IN ('"&ID_B&"') AND ingested_at > TIMESTAMP('"&$C$4&"') ORDER BY ingested_at" -> SELECT page_id, job_type, load_type, status, has_errors, error_details, revision, ingested_at FROM page_audit WHERE page_id IN ('43607') AND ingested_at > TIMESTAMP('<paste start time from step 1>') ORDER BY ingested_at | E17: last status = completed · no failed rows.
A18: 11 | B18: GCS (Console) | C18: Cloud Storage → Buckets → open the bucket shown → in 'Filter by name prefix' paste the path → open page.md. | D18: ="Bucket: "&GCS_MD&" Path: "&GCS_FOLDER&"/"&ID_B&"/page.md" -> Bucket: <MD_BUCKET> Path: <FOLDER>/43607/page.md | E18: crc32c hash = BEFORE (file byte-identical). Same check for page.html. If different → record (title heading may be inside the markdown).
A19: 12 | B19: GCS (Console) | C19: Cloud Storage → Buckets → open the bucket shown → in 'Filter by name prefix' paste the path → open metadata.json. | D19: ="Bucket: "&GCS_JSON&" Path: "&GCS_FOLDER&"/"&ID_B&"/metadata.json" -> Bucket: <JSON_BUCKET> Path: <FOLDER>/43607/metadata.json | E19: Updated after start time; contains 'Child B Renamed QA-ZX91'.

Sheet S07
A1: S07 – Multiple rapid updates to the same page
B2: Goal | C2: Several quick edits before one pipeline run: only the final version ends up in Spanner and GCS, with no duplicates.
B3: Pages used | C3: ="Child C "&ID_C -> Child C <CHILD_C_ID>
B4: Start time (UTC) | C4: <paste start time from step 1>
B5: Overall result | C5: Not run
A7: Step | B7: Where | C7: What to do | D7: Copy this (query / path / URL) | E7: Expected result (fields & values) | F7: Actual result | G7: Pass / Fail
A8: 1 | B8: Spanner Studio | C8: Record the start time. Run the query, copy the value and paste it into the yellow 'Start time' cell (C4) at the top of this sheet. | D8: SELECT CURRENT_TIMESTAMP() AS start_time | E8: One value like 2026-10-01T09:15:02.123456Z. After pasting it into C4, the queries below show it automatically.
A9: 2 | B9: Athena | C9: Within 2 minutes, edit Child C three times, publishing each time: 1) add a line 'QA-ZX91 rapid edit 1' 2) change it to 'QA-ZX91 rapid edit 2' 3) change it to 'QA-ZX91 rapid edit 3 FINAL' Write down the final revision number from Page history. | D9: - | E9: 3 new revisions in Athena.
A10: 3 | B10: Bruno | C10: Trigger the pipeline: open Bruno → collection hive-knowledge-preprocessing → environment INT → request 'incremental-job' → Send. Copy the job_id from the response. Open request 'job-status', put the job_id at the end of the URL, Send every ~1 minute until status is SUCCESS. | D10: ="POST "&API_URL&"/api/v1/jobs/incremental then GET "&API_URL&"/api/v1/jobs/<job_id>" -> POST <INT_BASE_URL>/api/v1/jobs/incremental then GET <INT_BASE_URL>/api/v1/jobs/<job_id> | E10: incremental-job returns a job_id. job-status ends with status = SUCCESS (not FAILED). If FAILED: screenshot the response, mark this sheet Fail, log a defect.
A11: 4 | B11: Spanner Studio | C11: Confirm the pipeline finished (a new run for root 39960 after your start time). | D11: ="SELECT page_id, job_run_id, status, since_time, watermark_time, ingested_at FROM page_since WHERE page_id = '"&ID_ROOT&"' AND ingested_at > TIMESTAMP('"&$C$4&"') ORDER BY ingested_at DESC" -> SELECT page_id, job_run_id, status, since_time, watermark_time, ingested_at FROM page_since WHERE page_id = '39960' AND ingested_at > TIMESTAMP('<paste start time from step 1>') ORDER BY ingested_at DESC | E11: At least 1 row: page_id = 39960, status = COMPLETED, ingested_at later than your start time. No row yet → wait a minute and re-run.
A12: 5 | B12: Spanner Studio | C12: Check the page has the final revision. | D12: ="SELECT page_id, revision, content_size, date_modified, ingested_at FROM page WHERE page_id = '"&ID_C&"'" -> SELECT page_id, revision, content_size, date_modified, ingested_at FROM page WHERE page_id = '<CHILD_C_ID>' | E12: revision = final Athena revision · ingested_at after start time.
A13: 6 | B13: Spanner Studio | C13: Check there are no duplicate links. | D13: ="SELECT dependency_page_id, type, COUNT(*) AS n FROM page_dependency WHERE page_id = '"&ID_C&"' GROUP BY dependency_page_id, type HAVING COUNT(*) > 1" -> SELECT dependency_page_id, type, COUNT(*) AS n FROM page_dependency WHERE page_id = '<CHILD_C_ID>' GROUP BY dependency_page_id, type HAVING COUNT(*) > 1 | E13: 0 rows.
A14: 7 | B14: Spanner Studio | C14: Check the audit trail. | D14: ="SELECT page_id, job_type, load_type, status, has_errors, error_details, revision, ingested_at FROM page_audit WHERE page_id IN ('"&ID_C&"') AND ingested_at > TIMESTAMP('"&$C$4&"') ORDER BY ingested_at" -> SELECT page_id, job_type, load_type, status, has_errors, error_details, revision, ingested_at FROM page_audit WHERE page_id IN ('<CHILD_C_ID>') AND ingested_at > TIMESTAMP('<paste start time from step 1>') ORDER BY ingested_at | E14: status = completed · no failed rows.
A15: 8 | B15: GCS (Console) | C15: Cloud Storage → Buckets → open the bucket shown → in 'Filter by name prefix' paste the path → open page.md. | D15: ="Bucket: "&GCS_MD&" Path: "&GCS_FOLDER&"/"&ID_C&"/page.md" -> Bucket: <MD_BUCKET> Path: <FOLDER>/<CHILD_C_ID>/page.md | E15: Contains 'rapid edit 3 FINAL' and does NOT contain 'rapid edit 1' or 'rapid edit 2'.

Sheet S08
A1: S08 – Content reverted to a previous revision
B2: Goal | C2: Edit a page, then restore the previous version in Athena: Spanner and GCS must end up with the reverted content.
B3: Pages used | C3: ="Parent B "&ID_PB -> Parent B 43603
B4: Start time (UTC) | C4: <paste start time from step 1> | D4: Second time (UTC) → | E4: <paste second time>
B5: Overall result | C5: Not run
A7: Step | B7: Where | C7: What to do | D7: Copy this (query / path / URL) | E7: Expected result (fields & values) | F7: Actual result | G7: Pass / Fail
A8: 1 | B8: Spanner Studio | C8: Record the start time. Run the query, copy the value and paste it into the yellow 'Start time' cell (C4) at the top of this sheet. | D8: SELECT CURRENT_TIMESTAMP() AS start_time | E8: One value like 2026-10-01T09:15:02.123456Z. After pasting it into C4, the queries below show it automatically.
A9: 2 | B9: Spanner Studio | C9: BEFORE: save the page row (Export → CSV, name S08_before). | D9: ="SELECT page_id, revision, content_size, revisions FROM page WHERE page_id = '"&ID_PB&"'" -> SELECT page_id, revision, content_size, revisions FROM page WHERE page_id = '43603' | E9: Note revision (R0) and content_size.
A10: 3 | B10: Athena | C10: Open Parent B → Edit → add the sentence 'QA-ZX91 TEMPORARY S8 EDIT' → Publish. Note the new revision (R1). | D10: - | E10: Revision R1 in Athena.
A11: 4 | B11: Bruno | C11: Trigger the pipeline: open Bruno → collection hive-knowledge-preprocessing → environment INT → request 'incremental-job' → Send. Copy the job_id from the response. Open request 'job-status', put the job_id at the end of the URL, Send every ~1 minute until status is SUCCESS. | D11: ="POST "&API_URL&"/api/v1/jobs/incremental then GET "&API_URL&"/api/v1/jobs/<job_id>" -> POST <INT_BASE_URL>/api/v1/jobs/incremental then GET <INT_BASE_URL>/api/v1/jobs/<job_id> | E11: incremental-job returns a job_id. job-status ends with status = SUCCESS (not FAILED). If FAILED: screenshot the response, mark this sheet Fail, log a defect.
A12: 5 | B12: Spanner Studio | C12: Confirm the pipeline finished (a new run for root 39960 after your start time). | D12: ="SELECT page_id, job_run_id, status, since_time, watermark_time, ingested_at FROM page_since WHERE page_id = '"&ID_ROOT&"' AND ingested_at > TIMESTAMP('"&$C$4&"') ORDER BY ingested_at DESC" -> SELECT page_id, job_run_id, status, since_time, watermark_time, ingested_at FROM page_since WHERE page_id = '39960' AND ingested_at > TIMESTAMP('<paste start time from step 1>') ORDER BY ingested_at DESC | E12: At least 1 row: page_id = 39960, status = COMPLETED, ingested_at later than your start time. No row yet → wait a minute and re-run.
A13: 6 | B13: Spanner Studio | C13: Checkpoint: the temporary edit reached Spanner. | D13: ="SELECT page_id, revision, content_size FROM page WHERE page_id = '"&ID_PB&"'" -> SELECT page_id, revision, content_size FROM page WHERE page_id = '43603' | E13: revision = R1.
A14: 7 | B14: Spanner Studio | C14: Record a second start time: run the query and paste the value into the yellow 'Second time' cell (E4). | D14: SELECT CURRENT_TIMESTAMP() AS second_time | E14: One timestamp value.
A15: 8 | B15: Athena | C15: Open Parent B → Page history → select the version R0 → Restore / Revert → Publish. Note the revision Athena now shows (R2). | D15: - | E15: Page content is back to the original.
A16: 9 | B16: Bruno | C16: Trigger the pipeline: open Bruno → collection hive-knowledge-preprocessing → environment INT → request 'incremental-job' → Send. Copy the job_id from the response. Open request 'job-status', put the job_id at the end of the URL, Send every ~1 minute until status is SUCCESS. | D16: ="POST "&API_URL&"/api/v1/jobs/incremental then GET "&API_URL&"/api/v1/jobs/<job_id>" -> POST <INT_BASE_URL>/api/v1/jobs/incremental then GET <INT_BASE_URL>/api/v1/jobs/<job_id> | E16: incremental-job returns a job_id. job-status ends with status = SUCCESS (not FAILED). If FAILED: screenshot the response, mark this sheet Fail, log a defect.
A17: 10 | B17: Spanner Studio | C17: Confirm the second pipeline run finished. | D17: ="SELECT page_id, status, ingested_at FROM page_since WHERE page_id = '"&ID_ROOT&"' AND ingested_at > TIMESTAMP('"&$E$4&"') ORDER BY ingested_at DESC" -> SELECT page_id, status, ingested_at FROM page_since WHERE page_id = '39960' AND ingested_at > TIMESTAMP('<paste second time>') ORDER BY ingested_at DESC | E17: At least 1 row, status = COMPLETED.
A18: 11 | B18: Spanner Studio | C18: Check the final page state. | D18: ="SELECT page_id, revision, content_size, revisions, ingested_at FROM page WHERE page_id = '"&ID_PB&"'" -> SELECT page_id, revision, content_size, revisions, ingested_at FROM page WHERE page_id = '43603' | E18: revision = R2 (Athena's latest) · content_size = BEFORE value · 'revisions' includes R1 · ingested_at after second time. FAIL if revision is still R1 → the revert was skipped (known risk: code ignores revisions not newer than the stored one).
A19: 12 | B19: Spanner Studio | C19: Check links are back to the baseline. | D19: ="SELECT dependency_page_id, type FROM page_dependency WHERE page_id = '"&ID_PB&"' ORDER BY dependency_page_id" -> SELECT dependency_page_id, type FROM page_dependency WHERE page_id = '43603' ORDER BY dependency_page_id | E19: Same as Setup_links_baseline for Parent B.
A20: 13 | B20: GCS (Console) | C20: Cloud Storage → Buckets → open the bucket shown → in 'Filter by name prefix' paste the path → open page.md. | D20: ="Bucket: "&GCS_MD&" Path: "&GCS_FOLDER&"/"&ID_PB&"/page.md" -> Bucket: <MD_BUCKET> Path: <FOLDER>/43603/page.md | E20: Updated after the second time; does NOT contain 'TEMPORARY S8 EDIT'.

Sheet S10
A1: S10 – Page moved to a different parent
B2: Goal | C2: Moving a page keeps one Spanner row (same page_id) with an updated path, and moves the parent link from the old parent to the new one.
B3: Pages used | C3: ="Child C "&ID_C&": moves from Parent B "&ID_PB&" to Parent A "&ID_PA -> Child C <CHILD_C_ID>: moves from Parent B 43603 to Parent A 43601
B4: Start time (UTC) | C4: <paste start time from step 1>
B5: Overall result | C5: Not run
A7: Step | B7: Where | C7: What to do | D7: Copy this (query / path / URL) | E7: Expected result (fields & values) | F7: Actual result | G7: Pass / Fail
A8: 1 | B8: Spanner Studio | C8: Record the start time. Run the query, copy the value and paste it into the yellow 'Start time' cell (C4) at the top of this sheet. | D8: SELECT CURRENT_TIMESTAMP() AS start_time | E8: One value like 2026-10-01T09:15:02.123456Z. After pasting it into C4, the queries below show it automatically.
A9: 2 | B9: Spanner Studio | C9: BEFORE: save the parent links (Export → CSV, name S10_before). | D9: ="SELECT page_id, dependency_page_id, type FROM page_dependency WHERE dependency_page_id = '"&ID_C&"' AND type = 'subpage'" -> SELECT page_id, dependency_page_id, type FROM page_dependency WHERE dependency_page_id = '<CHILD_C_ID>' AND type = 'subpage' | E9: ="1 row: page_id = "&ID_PB&" (Parent B)." -> 1 row: page_id = 43603 (Parent B).
A10: 3 | B10: Athena | C10: Open Child C → Options → Move → choose Parent A as the new parent → confirm. | D10: - | E10: Child C now appears under Parent A.
A11: 4 | B11: Bruno | C11: Trigger the pipeline: open Bruno → collection hive-knowledge-preprocessing → environment INT → request 'incremental-job' → Send. Copy the job_id from the response. Open request 'job-status', put the job_id at the end of the URL, Send every ~1 minute until status is SUCCESS. | D11: ="POST "&API_URL&"/api/v1/jobs/incremental then GET "&API_URL&"/api/v1/jobs/<job_id>" -> POST <INT_BASE_URL>/api/v1/jobs/incremental then GET <INT_BASE_URL>/api/v1/jobs/<job_id> | E11: incremental-job returns a job_id. job-status ends with status = SUCCESS (not FAILED). If FAILED: screenshot the response, mark this sheet Fail, log a defect.
A12: 5 | B12: Spanner Studio | C12: Confirm the pipeline finished (a new run for root 39960 after your start time). | D12: ="SELECT page_id, job_run_id, status, since_time, watermark_time, ingested_at FROM page_since WHERE page_id = '"&ID_ROOT&"' AND ingested_at > TIMESTAMP('"&$C$4&"') ORDER BY ingested_at DESC" -> SELECT page_id, job_run_id, status, since_time, watermark_time, ingested_at FROM page_since WHERE page_id = '39960' AND ingested_at > TIMESTAMP('<paste start time from step 1>') ORDER BY ingested_at DESC | E12: At least 1 row: page_id = 39960, status = COMPLETED, ingested_at later than your start time. No row yet → wait a minute and re-run.
A13: 6 | B13: Spanner Studio | C13: Check the page path changed but the ID did not. | D13: ="SELECT page_id, title, path, revision, ingested_at FROM page WHERE page_id = '"&ID_C&"'" -> SELECT page_id, title, path, revision, ingested_at FROM page WHERE page_id = '<CHILD_C_ID>' | E13: 1 row · path = Customer_Vulnerability_Hub_2/Vulnerabilities/Test_Area/Parent_A/Child_C · ingested_at after start time.
A14: 7 | B14: Spanner Studio | C14: Check there is only one Child C page. | D14: SELECT COUNT(*) AS n FROM page WHERE title = 'Child C' | E14: n = 1.
A15: 8 | B15: Spanner Studio | C15: Check the parent link moved. | D15: ="SELECT page_id, dependency_page_id, type FROM page_dependency WHERE dependency_page_id = '"&ID_C&"' AND type = 'subpage'" -> SELECT page_id, dependency_page_id, type FROM page_dependency WHERE dependency_page_id = '<CHILD_C_ID>' AND type = 'subpage' | E15: ="Exactly 1 row: page_id = "&ID_PA&" (Parent A). NO row with page_id = "&ID_PB&"." -> Exactly 1 row: page_id = 43601 (Parent A). NO row with page_id = 43603.
A16: 9 | B16: Spanner Studio | C16: Check other links to Child C still work. | D16: ="SELECT page_id, dependency_page_id, type, is_broken FROM page_dependency WHERE dependency_page_id = '"&ID_C&"' AND type != 'subpage'" -> SELECT page_id, dependency_page_id, type, is_broken FROM page_dependency WHERE dependency_page_id = '<CHILD_C_ID>' AND type != 'subpage' | E16: ="Row from QA Multi-Link S15 ("&ID_S15&") still present · is_broken = false." -> Row from QA Multi-Link S15 (<S15_ID>) still present · is_broken = false.
A17: 10 | B17: Spanner Studio | C17: Check the audit trail. | D17: ="SELECT page_id, job_type, load_type, status, has_errors, error_details, revision, ingested_at FROM page_audit WHERE page_id IN ('"&ID_C&"', '"&ID_PA&"', '"&ID_PB&"') AND ingested_at > TIMESTAMP('"&$C$4&"') ORDER BY ingested_at" -> SELECT page_id, job_type, load_type, status, has_errors, error_details, revision, ingested_at FROM page_audit WHERE page_id IN ('<CHILD_C_ID>', '43601', '43603') AND ingested_at > TIMESTAMP('<paste start time from step 1>') ORDER BY ingested_at | E17: completed rows for Child C and both parents · no failed rows.
